<?xml version="1.0"?>
<robot xmlns:xacro="http://www.ros.org/wiki/xacro">

    <xacro:property name="chassis_lengthhh" value="0.3"/>

    <material name="blue">
        <color rgba="0 0 0.8 1"/>
    </material>

    <material name="red">
        <color rgba="0.8 0 0 1"/>
    </material>

    <material name="green">
        <color rgba="0.5 0.99 0.03 1"/>
    </material>

    <material name="pink">
        <color rgba="1.0 0.7 0.8 1"/>
    </material>


    <!-- BASE_LINK -->

    <link name="base_link">
        <visual>
            <geometry>
                <cylinder length="0.1" radius="0.1"/>
            </geometry>
            <material name="green"/>
        </visual>
    </link>



    <!-- BASE_FOOTPRINT -->

    <link name="base_footprint">

    </link>

    <joint name="base_joint" type="fixed">
        <parent link="base_link"/>
        <child link="base_footprint"/>
        <origin xyz="0.0 0.0 0.0" rpy="0 0 0"/>
    </joint>



    <!-- CHASSIS -->

    <link name="chassis">
        <visual>
            <geometry>
                <box size="0.290 0.185 0.004"/>
            </geometry>
            <material name="pink"/>
            <origin rpy="0 0 0" xyz="0 0 0"/>
        </visual>
    </link>

    <joint name="base_to_chassis" type="fixed">
        <parent link="base_link"/>
        <child link="chassis"/>
        <origin rpy="0 0 0" xyz="0 0 0.125"/>
        <axis xyz="0 0 1"/>
    </joint>



    <!-- FRONT RIGHT WHEEL LINK -->

    <link name="wheel_front_right">
        <visual>
            <geometry>
                <cylinder length="0.055" radius="0.065"/>
            </geometry>
            <material name="blue"/>
        </visual>
    </link>

    <joint name="motor_0" type="continuous">
        <parent link="base_link"/>
        <child link="wheel_front_right"/>
        <origin xyz="0.120 -0.140 0.0" rpy="1.57 0 0"/>
        <axis xyz="0 0 1"/>
    </joint>



    <!-- FRONT LEFT WHEEL LINK -->

    <link name="wheel_front_left">
        <visual>
            <geometry>
                <cylinder length="0.055" radius="0.065"/>
            </geometry>
            <material name="blue"/>
        </visual>
    </link>

    <joint name="motor_1" type="continuous">
        <parent link="base_link"/>
        <child link="wheel_front_left"/>
        <origin xyz="0.120 0.140 0.0" rpy="1.57 0 0"/>
        <axis xyz="0 0 -1"/>
    </joint>



    <!-- BACK RIGHT WHEEL LINK -->

    <link name="wheel_back_right">
        <visual>
            <geometry>
                <cylinder length="0.055" radius="0.065"/>
            </geometry>
            <material name="red"/>
        </visual>
    </link>

    <joint name="motor_2" type="continuous">
        <parent link="base_link"/>
        <child link="wheel_back_right"/>
        <origin xyz="-0.120 -0.140 0.0" rpy="1.57 0 0"/>
        <axis xyz="0 0 1"/>
    </joint>



    <!-- BACK LEFT WHEEL LINK -->

    <link name="wheel_back_left">
        <visual>
            <geometry>
                <cylinder length="0.055" radius="0.065"/>
            </geometry>
            <material name="red"/>
        </visual>
    </link>

    <joint name="motor_3" type="continuous">
        <parent link="base_link"/>
        <child link="wheel_back_left"/>
        <origin xyz="-0.120 0.140 0.0" rpy="1.57 0 0"/>
        <axis xyz="0 0 -1"/>
    </joint>

</robot>
