<?xml version="1.0"?>
<robot name="DDD">

  <material name="blue">
    <color rgba="0 0 0.8 1"/>
  </material>

  <material name="red">
    <color rgba="0.8 0 0 1"/>
  </material>

  <material name="green">
    <color rgba="0.5 0.99 0.03 1"/>
  </material>

  <material name="pink">
    <color rgba="1.0 0.7 0.8 1"/>
  </material>

  <link name="wheel_front_right">
    <visual>
      <geometry>
        <cylinder length="0.055" radius="0.065"/>
      </geometry>
      <material name="blue"/>
    </visual>
  </link>

  <link name="wheel_front_left">
    <visual>
      <geometry>
        <cylinder length="0.055" radius="0.065"/>
      </geometry>
      <material name="blue"/>
    </visual>
  </link>

  <link name="wheel_back_right">
    <visual>
      <geometry>
        <cylinder length="0.055" radius="0.065"/>
      </geometry>
      <material name="red"/>
    </visual>
  </link>

  <link name="wheel_back_left">
    <visual>
      <geometry>
        <cylinder length="0.055" radius="0.065"/>
      </geometry>
      <material name="red"/>
    </visual>
  </link>
 
  <!-- <link name="wheel_center">
    <visual>
      <geometry>
        <cylinder length="0.055" radius="0.065"/>
      </geometry>
      <material name="blue"/>
      <origin rpy="0 ${pi/2} 0" xyz="0 0 0"/>
    </visual>
  </link> -->
 
  <link name="base_link">
    <visual>
      <geometry>
        <cylinder length="0.1" radius="0.1"/>
      </geometry>
      <material name="green"/>
    </visual>
  </link>

  <link name="chassis">
    <visual>
      <geometry>
        <box size="0.290 0.185 0.004"/>
      </geometry>
      <material name="pink"/>
      <origin rpy="0 0 0" xyz="0 0 0"/>
    </visual>
  </link>

  <link name="laser">
    <visual>
        <geometry>
            <cylinder radius="0.05" length="0.04"/>
        </geometry>
        <material name="red"/>
        <origin rpy="0 0 0" xyz="0 0 0"/>
    </visual>
  </link>

  <link name="camera_link">
    <visual>
        <geometry>
            <box size="0.010 0.03 0.03"/>
        </geometry>
        <material name="red"/>
        <origin rpy="0 0 0" xyz="0 0 0"/>
    </visual>
  </link>

  <link name="camera_link_optical"></link>
  
  <link name="base_footprint"/>

  <joint name="base_joint" type="fixed">
    <parent link="base_link"/>
    <child link="base_footprint"/>
    <origin xyz="0.0 0.0 0.0" rpy="0 0 0"/>
  </joint>
  
  
  <joint name="base_to_chassis" type="fixed">
    <parent link="base_link"/>
    <child link="chassis"/>
    <origin rpy="0 0 0" xyz="0 0 0.125"/>
    <axis xyz="0 0 1"/>
  </joint>
  
  <joint name="motor_0" type="continuous">
    <parent link="base_link"/>
    <child link="wheel_front_right"/>
    <origin xyz="0.120 -0.140 0.0" rpy="1.57 0 0"/>
    <axis xyz="0 0 1"/>
  </joint>
  
  <joint name="motor_1" type="continuous">
    <parent link="base_link"/>
    <child link="wheel_front_left"/>
    <origin xyz="0.120 0.140 0.0" rpy="1.57 0 0"/>
    <axis xyz="0 0 -1"/>
  </joint>

  <joint name="motor_2" type="continuous">
    <parent link="base_link"/>
    <child link="wheel_back_right"/>
    <origin xyz="-0.120 -0.140 0.0" rpy="1.57 0 0"/>
    <axis xyz="0 0 1"/>
  </joint>
  
  <joint name="motor_3" type="continuous">
    <parent link="base_link"/>
    <child link="wheel_back_left"/>
    <origin xyz="-0.120 0.140 0.0" rpy="1.57 0 0"/>
    <axis xyz="0 0 -1"/>
  </joint>
  
  <joint name="chassis_to_lidar" type="fixed">
    <parent link="chassis"/>
    <child link="laser"/>
    <origin xyz="-0.065 0.0 0.09" rpy="0 0 0"/>
    <axis xyz="0 0 1"/>
  </joint>

  <joint name="chassis_to_camera_link" type="fixed">
    <parent link="chassis"/>
    <child link="camera_link"/>
    <origin xyz="0.065 0.0 0.09" rpy="0 0 0"/>
  </joint>

  <joint name="chassis_to_camera_link_optical" type="fixed">
    <parent link="camera_link"/>
    <child link="camera_link_optical"/>
    <origin xyz="0.0 0.0 0.0" rpy="${-pi/2} 0 ${-pi/2}"/>
  </joint>
  
</robot>